{
 "cells": [
  {
   "cell_type": "code",
   "execution_count": 1,
   "id": "54b0d8a4",
   "metadata": {},
   "outputs": [],
   "source": [
    "import tensorflow as tf\n",
    "import numpy as np\n",
    "import matplotlib.pyplot as plt"
   ]
  },
  {
   "cell_type": "code",
   "execution_count": 2,
   "id": "e4575024",
   "metadata": {},
   "outputs": [],
   "source": [
    "# build data\n",
    "x_data = np.linspace(-0.5,0.5,200)[:,np.newaxis]\n",
    "noise = np.random.normal(0,0.02,x_data.shape)\n",
    "y_data = np.square(x_data) + noise"
   ]
  },
  {
   "cell_type": "code",
   "execution_count": 3,
   "id": "244db373",
   "metadata": {},
   "outputs": [
    {
     "name": "stdout",
     "output_type": "stream",
     "text": [
      "WARNING:tensorflow:From C:\\TempUser\\ipykernel_49792\\3203451539.py:2: The name tf.placeholder is deprecated. Please use tf.compat.v1.placeholder instead.\n",
      "\n"
     ]
    }
   ],
   "source": [
    "# use placeholder to store data\n",
    "x = tf.placeholder(tf.float32,[None,1])\n",
    "y = tf.placeholder(tf.float32,[None,1])"
   ]
  },
  {
   "cell_type": "code",
   "execution_count": null,
   "id": "025961da",
   "metadata": {},
   "outputs": [
    {
     "name": "stdout",
     "output_type": "stream",
     "text": [
      "WARNING:tensorflow:From C:\\TempUser\\ipykernel_49792\\4129811230.py:2: The name tf.random_normal is deprecated. Please use tf.random.normal instead.\n",
      "\n"
     ]
    },
    {
     "name": "stderr",
     "output_type": "stream",
     "text": [
      "ERROR:root:Internal Python error in the inspect module.\n",
      "Below is the traceback from this internal error.\n",
      "\n",
      "ERROR:root:Internal Python error in the inspect module.\n",
      "Below is the traceback from this internal error.\n",
      "\n",
      "ERROR:root:Internal Python error in the inspect module.\n",
      "Below is the traceback from this internal error.\n",
      "\n"
     ]
    },
    {
     "name": "stdout",
     "output_type": "stream",
     "text": [
      "Traceback (most recent call last):\n",
      "  File \"C:\\ProgramData\\Anaconda3\\envs\\deeplearning\\lib\\site-packages\\IPython\\core\\interactiveshell.py\", line 3457, in run_code\n",
      "    exec(code_obj, self.user_global_ns, self.user_ns)\n",
      "  File \"C:\\TempUser\\ipykernel_49792\\4129811230.py\", line 4, in <module>\n",
      "    WeightPlusBias_L1 = tf.matmul(x,Weights_L1)+biases_L1\n",
      "NameError: name 'Weights_L1' is not defined\n",
      "\n",
      "During handling of the above exception, another exception occurred:\n",
      "\n",
      "Traceback (most recent call last):\n",
      "  File \"C:\\ProgramData\\Anaconda3\\envs\\deeplearning\\lib\\site-packages\\IPython\\core\\interactiveshell.py\", line 2077, in showtraceback\n",
      "    stb = value._render_traceback_()\n",
      "AttributeError: 'NameError' object has no attribute '_render_traceback_'\n",
      "\n",
      "During handling of the above exception, another exception occurred:\n",
      "\n",
      "Traceback (most recent call last):\n",
      "  File \"C:\\ProgramData\\Anaconda3\\envs\\deeplearning\\lib\\site-packages\\IPython\\core\\ultratb.py\", line 1101, in get_records\n",
      "    return _fixed_getinnerframes(etb, number_of_lines_of_context, tb_offset)\n",
      "  File \"C:\\ProgramData\\Anaconda3\\envs\\deeplearning\\lib\\site-packages\\IPython\\core\\ultratb.py\", line 248, in wrapped\n",
      "    return f(*args, **kwargs)\n",
      "  File \"C:\\ProgramData\\Anaconda3\\envs\\deeplearning\\lib\\site-packages\\IPython\\core\\ultratb.py\", line 281, in _fixed_getinnerframes\n",
      "    records = fix_frame_records_filenames(inspect.getinnerframes(etb, context))\n",
      "  File \"C:\\ProgramData\\Anaconda3\\envs\\deeplearning\\lib\\inspect.py\", line 1500, in getinnerframes\n",
      "    frameinfo = (tb.tb_frame,) + getframeinfo(tb, context)\n",
      "  File \"C:\\ProgramData\\Anaconda3\\envs\\deeplearning\\lib\\inspect.py\", line 1458, in getframeinfo\n",
      "    filename = getsourcefile(frame) or getfile(frame)\n",
      "  File \"C:\\ProgramData\\Anaconda3\\envs\\deeplearning\\lib\\inspect.py\", line 696, in getsourcefile\n",
      "    if getattr(getmodule(object, filename), '__loader__', None) is not None:\n",
      "  File \"C:\\ProgramData\\Anaconda3\\envs\\deeplearning\\lib\\inspect.py\", line 733, in getmodule\n",
      "    if ismodule(module) and hasattr(module, '__file__'):\n",
      "  File \"C:\\ProgramData\\Anaconda3\\envs\\deeplearning\\lib\\site-packages\\tensorflow\\__init__.py\", line 50, in __getattr__\n",
      "    module = self._load()\n",
      "  File \"C:\\ProgramData\\Anaconda3\\envs\\deeplearning\\lib\\site-packages\\tensorflow\\__init__.py\", line 44, in _load\n",
      "    module = _importlib.import_module(self.__name__)\n",
      "  File \"C:\\ProgramData\\Anaconda3\\envs\\deeplearning\\lib\\importlib\\__init__.py\", line 127, in import_module\n",
      "    return _bootstrap._gcd_import(name[level:], package, level)\n",
      "  File \"<frozen importlib._bootstrap>\", line 1006, in _gcd_import\n",
      "  File \"<frozen importlib._bootstrap>\", line 983, in _find_and_load\n",
      "  File \"<frozen importlib._bootstrap>\", line 967, in _find_and_load_unlocked\n",
      "  File \"<frozen importlib._bootstrap>\", line 677, in _load_unlocked\n",
      "  File \"<frozen importlib._bootstrap_external>\", line 728, in exec_module\n",
      "  File \"<frozen importlib._bootstrap>\", line 219, in _call_with_frames_removed\n",
      "  File \"C:\\ProgramData\\Anaconda3\\envs\\deeplearning\\lib\\site-packages\\tensorflow_core\\contrib\\__init__.py\", line 39, in <module>\n",
      "    from tensorflow.contrib import compiler\n",
      "  File \"C:\\ProgramData\\Anaconda3\\envs\\deeplearning\\lib\\site-packages\\tensorflow_core\\contrib\\compiler\\__init__.py\", line 21, in <module>\n",
      "    from tensorflow.contrib.compiler import jit\n",
      "  File \"C:\\ProgramData\\Anaconda3\\envs\\deeplearning\\lib\\site-packages\\tensorflow_core\\contrib\\compiler\\__init__.py\", line 22, in <module>\n",
      "    from tensorflow.contrib.compiler import xla\n",
      "  File \"C:\\ProgramData\\Anaconda3\\envs\\deeplearning\\lib\\site-packages\\tensorflow_core\\contrib\\compiler\\xla.py\", line 22, in <module>\n",
      "    from tensorflow.python.estimator import model_fn as model_fn_lib\n",
      "  File \"C:\\ProgramData\\Anaconda3\\envs\\deeplearning\\lib\\site-packages\\tensorflow_core\\python\\estimator\\model_fn.py\", line 26, in <module>\n",
      "    from tensorflow_estimator.python.estimator import model_fn\n",
      "  File \"C:\\ProgramData\\Anaconda3\\envs\\deeplearning\\lib\\site-packages\\tensorflow_estimator\\__init__.py\", line 10, in <module>\n",
      "    from tensorflow_estimator._api.v1 import estimator\n",
      "  File \"C:\\ProgramData\\Anaconda3\\envs\\deeplearning\\lib\\site-packages\\tensorflow_estimator\\_api\\v1\\estimator\\__init__.py\", line 10, in <module>\n",
      "    from tensorflow_estimator._api.v1.estimator import experimental\n",
      "  File \"C:\\ProgramData\\Anaconda3\\envs\\deeplearning\\lib\\site-packages\\tensorflow_estimator\\_api\\v1\\estimator\\experimental\\__init__.py\", line 10, in <module>\n",
      "    from tensorflow_estimator.python.estimator.canned.dnn import dnn_logit_fn_builder\n",
      "  File \"C:\\ProgramData\\Anaconda3\\envs\\deeplearning\\lib\\site-packages\\tensorflow_estimator\\python\\estimator\\canned\\dnn.py\", line 27, in <module>\n",
      "    from tensorflow_estimator.python.estimator import estimator\n",
      "  File \"C:\\ProgramData\\Anaconda3\\envs\\deeplearning\\lib\\site-packages\\tensorflow_estimator\\python\\estimator\\estimator.py\", line 36, in <module>\n",
      "    from tensorflow.python.profiler import trace\n",
      "ImportError: cannot import name 'trace' from 'tensorflow.python.profiler' (C:\\ProgramData\\Anaconda3\\envs\\deeplearning\\lib\\site-packages\\tensorflow_core\\python\\profiler\\__init__.py)\n",
      "Traceback (most recent call last):\n",
      "  File \"C:\\ProgramData\\Anaconda3\\envs\\deeplearning\\lib\\site-packages\\IPython\\core\\interactiveshell.py\", line 3457, in run_code\n",
      "    exec(code_obj, self.user_global_ns, self.user_ns)\n",
      "  File \"C:\\TempUser\\ipykernel_49792\\4129811230.py\", line 4, in <module>\n",
      "    WeightPlusBias_L1 = tf.matmul(x,Weights_L1)+biases_L1\n",
      "NameError: name 'Weights_L1' is not defined\n",
      "\n",
      "During handling of the above exception, another exception occurred:\n",
      "\n",
      "Traceback (most recent call last):\n",
      "  File \"C:\\ProgramData\\Anaconda3\\envs\\deeplearning\\lib\\site-packages\\IPython\\core\\interactiveshell.py\", line 2077, in showtraceback\n",
      "    stb = value._render_traceback_()\n",
      "AttributeError: 'NameError' object has no attribute '_render_traceback_'\n",
      "\n",
      "During handling of the above exception, another exception occurred:\n",
      "\n",
      "Traceback (most recent call last):\n",
      "  File \"C:\\ProgramData\\Anaconda3\\envs\\deeplearning\\lib\\site-packages\\IPython\\core\\interactiveshell.py\", line 3377, in run_ast_nodes\n",
      "    if (await self.run_code(code, result,  async_=asy)):\n",
      "  File \"C:\\ProgramData\\Anaconda3\\envs\\deeplearning\\lib\\site-packages\\IPython\\core\\interactiveshell.py\", line 3474, in run_code\n",
      "    self.showtraceback(running_compiled_code=True)\n",
      "  File \"C:\\ProgramData\\Anaconda3\\envs\\deeplearning\\lib\\site-packages\\IPython\\core\\interactiveshell.py\", line 2080, in showtraceback\n",
      "    value, tb, tb_offset=tb_offset)\n",
      "  File \"C:\\ProgramData\\Anaconda3\\envs\\deeplearning\\lib\\site-packages\\IPython\\core\\ultratb.py\", line 1368, in structured_traceback\n",
      "    self, etype, value, tb, tb_offset, number_of_lines_of_context)\n",
      "  File \"C:\\ProgramData\\Anaconda3\\envs\\deeplearning\\lib\\site-packages\\IPython\\core\\ultratb.py\", line 1268, in structured_traceback\n",
      "    self, etype, value, tb, tb_offset, number_of_lines_of_context\n",
      "  File \"C:\\ProgramData\\Anaconda3\\envs\\deeplearning\\lib\\site-packages\\IPython\\core\\ultratb.py\", line 1125, in structured_traceback\n",
      "    tb_offset)\n",
      "  File \"C:\\ProgramData\\Anaconda3\\envs\\deeplearning\\lib\\site-packages\\IPython\\core\\ultratb.py\", line 1082, in format_exception_as_a_whole\n",
      "    last_unique, recursion_repeat = find_recursion(orig_etype, evalue, records)\n",
      "  File \"C:\\ProgramData\\Anaconda3\\envs\\deeplearning\\lib\\site-packages\\IPython\\core\\ultratb.py\", line 382, in find_recursion\n",
      "    return len(records), 0\n",
      "TypeError: object of type 'NoneType' has no len()\n",
      "\n",
      "During handling of the above exception, another exception occurred:\n",
      "\n",
      "Traceback (most recent call last):\n",
      "  File \"C:\\ProgramData\\Anaconda3\\envs\\deeplearning\\lib\\site-packages\\IPython\\core\\interactiveshell.py\", line 2077, in showtraceback\n",
      "    stb = value._render_traceback_()\n",
      "AttributeError: 'TypeError' object has no attribute '_render_traceback_'\n",
      "\n",
      "During handling of the above exception, another exception occurred:\n",
      "\n",
      "Traceback (most recent call last):\n",
      "  File \"C:\\ProgramData\\Anaconda3\\envs\\deeplearning\\lib\\site-packages\\IPython\\core\\ultratb.py\", line 1101, in get_records\n",
      "    return _fixed_getinnerframes(etb, number_of_lines_of_context, tb_offset)\n",
      "  File \"C:\\ProgramData\\Anaconda3\\envs\\deeplearning\\lib\\site-packages\\IPython\\core\\ultratb.py\", line 248, in wrapped\n",
      "    return f(*args, **kwargs)\n",
      "  File \"C:\\ProgramData\\Anaconda3\\envs\\deeplearning\\lib\\site-packages\\IPython\\core\\ultratb.py\", line 281, in _fixed_getinnerframes\n",
      "    records = fix_frame_records_filenames(inspect.getinnerframes(etb, context))\n",
      "  File \"C:\\ProgramData\\Anaconda3\\envs\\deeplearning\\lib\\inspect.py\", line 1500, in getinnerframes\n",
      "    frameinfo = (tb.tb_frame,) + getframeinfo(tb, context)\n",
      "  File \"C:\\ProgramData\\Anaconda3\\envs\\deeplearning\\lib\\inspect.py\", line 1458, in getframeinfo\n",
      "    filename = getsourcefile(frame) or getfile(frame)\n",
      "  File \"C:\\ProgramData\\Anaconda3\\envs\\deeplearning\\lib\\inspect.py\", line 696, in getsourcefile\n",
      "    if getattr(getmodule(object, filename), '__loader__', None) is not None:\n",
      "  File \"C:\\ProgramData\\Anaconda3\\envs\\deeplearning\\lib\\inspect.py\", line 733, in getmodule\n",
      "    if ismodule(module) and hasattr(module, '__file__'):\n",
      "  File \"C:\\ProgramData\\Anaconda3\\envs\\deeplearning\\lib\\site-packages\\tensorflow\\__init__.py\", line 50, in __getattr__\n",
      "    module = self._load()\n",
      "  File \"C:\\ProgramData\\Anaconda3\\envs\\deeplearning\\lib\\site-packages\\tensorflow\\__init__.py\", line 44, in _load\n",
      "    module = _importlib.import_module(self.__name__)\n",
      "  File \"C:\\ProgramData\\Anaconda3\\envs\\deeplearning\\lib\\importlib\\__init__.py\", line 127, in import_module\n",
      "    return _bootstrap._gcd_import(name[level:], package, level)\n",
      "  File \"<frozen importlib._bootstrap>\", line 1006, in _gcd_import\n",
      "  File \"<frozen importlib._bootstrap>\", line 983, in _find_and_load\n",
      "  File \"<frozen importlib._bootstrap>\", line 965, in _find_and_load_unlocked\n",
      "ModuleNotFoundError: No module named 'tensorflow_core.estimator'\n",
      "Traceback (most recent call last):\n",
      "  File \"C:\\ProgramData\\Anaconda3\\envs\\deeplearning\\lib\\site-packages\\IPython\\core\\interactiveshell.py\", line 3457, in run_code\n",
      "    exec(code_obj, self.user_global_ns, self.user_ns)\n",
      "  File \"C:\\TempUser\\ipykernel_49792\\4129811230.py\", line 4, in <module>\n",
      "    WeightPlusBias_L1 = tf.matmul(x,Weights_L1)+biases_L1\n",
      "NameError: name 'Weights_L1' is not defined\n",
      "\n",
      "During handling of the above exception, another exception occurred:\n",
      "\n",
      "Traceback (most recent call last):\n",
      "  File \"C:\\ProgramData\\Anaconda3\\envs\\deeplearning\\lib\\site-packages\\IPython\\core\\interactiveshell.py\", line 2077, in showtraceback\n",
      "    stb = value._render_traceback_()\n",
      "AttributeError: 'NameError' object has no attribute '_render_traceback_'\n",
      "\n",
      "During handling of the above exception, another exception occurred:\n",
      "\n",
      "Traceback (most recent call last):\n",
      "  File \"C:\\ProgramData\\Anaconda3\\envs\\deeplearning\\lib\\site-packages\\IPython\\core\\interactiveshell.py\", line 3377, in run_ast_nodes\n",
      "    if (await self.run_code(code, result,  async_=asy)):\n",
      "  File \"C:\\ProgramData\\Anaconda3\\envs\\deeplearning\\lib\\site-packages\\IPython\\core\\interactiveshell.py\", line 3474, in run_code\n",
      "    self.showtraceback(running_compiled_code=True)\n",
      "  File \"C:\\ProgramData\\Anaconda3\\envs\\deeplearning\\lib\\site-packages\\IPython\\core\\interactiveshell.py\", line 2080, in showtraceback\n",
      "    value, tb, tb_offset=tb_offset)\n",
      "  File \"C:\\ProgramData\\Anaconda3\\envs\\deeplearning\\lib\\site-packages\\IPython\\core\\ultratb.py\", line 1368, in structured_traceback\n",
      "    self, etype, value, tb, tb_offset, number_of_lines_of_context)\n",
      "  File \"C:\\ProgramData\\Anaconda3\\envs\\deeplearning\\lib\\site-packages\\IPython\\core\\ultratb.py\", line 1268, in structured_traceback\n",
      "    self, etype, value, tb, tb_offset, number_of_lines_of_context\n",
      "  File \"C:\\ProgramData\\Anaconda3\\envs\\deeplearning\\lib\\site-packages\\IPython\\core\\ultratb.py\", line 1125, in structured_traceback\n",
      "    tb_offset)\n",
      "  File \"C:\\ProgramData\\Anaconda3\\envs\\deeplearning\\lib\\site-packages\\IPython\\core\\ultratb.py\", line 1082, in format_exception_as_a_whole\n",
      "    last_unique, recursion_repeat = find_recursion(orig_etype, evalue, records)\n",
      "  File \"C:\\ProgramData\\Anaconda3\\envs\\deeplearning\\lib\\site-packages\\IPython\\core\\ultratb.py\", line 382, in find_recursion\n",
      "    return len(records), 0\n",
      "TypeError: object of type 'NoneType' has no len()\n",
      "\n",
      "During handling of the above exception, another exception occurred:\n",
      "\n",
      "Traceback (most recent call last):\n",
      "  File \"C:\\ProgramData\\Anaconda3\\envs\\deeplearning\\lib\\site-packages\\IPython\\core\\interactiveshell.py\", line 2077, in showtraceback\n",
      "    stb = value._render_traceback_()\n",
      "AttributeError: 'TypeError' object has no attribute '_render_traceback_'\n",
      "\n",
      "During handling of the above exception, another exception occurred:\n",
      "\n",
      "Traceback (most recent call last):\n",
      "  File \"C:\\ProgramData\\Anaconda3\\envs\\deeplearning\\lib\\site-packages\\IPython\\core\\interactiveshell.py\", line 2960, in _run_cell\n",
      "    return runner(coro)\n",
      "  File \"C:\\ProgramData\\Anaconda3\\envs\\deeplearning\\lib\\site-packages\\IPython\\core\\async_helpers.py\", line 78, in _pseudo_sync_runner\n",
      "    coro.send(None)\n",
      "  File \"C:\\ProgramData\\Anaconda3\\envs\\deeplearning\\lib\\site-packages\\IPython\\core\\interactiveshell.py\", line 3186, in run_cell_async\n",
      "    interactivity=interactivity, compiler=compiler, result=result)\n",
      "  File \"C:\\ProgramData\\Anaconda3\\envs\\deeplearning\\lib\\site-packages\\IPython\\core\\interactiveshell.py\", line 3396, in run_ast_nodes\n",
      "    self.showtraceback()\n",
      "  File \"C:\\ProgramData\\Anaconda3\\envs\\deeplearning\\lib\\site-packages\\IPython\\core\\interactiveshell.py\", line 2080, in showtraceback\n",
      "    value, tb, tb_offset=tb_offset)\n",
      "  File \"C:\\ProgramData\\Anaconda3\\envs\\deeplearning\\lib\\site-packages\\IPython\\core\\ultratb.py\", line 1368, in structured_traceback\n",
      "    self, etype, value, tb, tb_offset, number_of_lines_of_context)\n",
      "  File \"C:\\ProgramData\\Anaconda3\\envs\\deeplearning\\lib\\site-packages\\IPython\\core\\ultratb.py\", line 1268, in structured_traceback\n",
      "    self, etype, value, tb, tb_offset, number_of_lines_of_context\n",
      "  File \"C:\\ProgramData\\Anaconda3\\envs\\deeplearning\\lib\\site-packages\\IPython\\core\\ultratb.py\", line 1143, in structured_traceback\n",
      "    chained_exceptions_tb_offset)\n",
      "  File \"C:\\ProgramData\\Anaconda3\\envs\\deeplearning\\lib\\site-packages\\IPython\\core\\ultratb.py\", line 1082, in format_exception_as_a_whole\n",
      "    last_unique, recursion_repeat = find_recursion(orig_etype, evalue, records)\n",
      "  File \"C:\\ProgramData\\Anaconda3\\envs\\deeplearning\\lib\\site-packages\\IPython\\core\\ultratb.py\", line 382, in find_recursion\n",
      "    return len(records), 0\n",
      "TypeError: object of type 'NoneType' has no len()\n",
      "\n",
      "During handling of the above exception, another exception occurred:\n",
      "\n",
      "Traceback (most recent call last):\n",
      "  File \"C:\\ProgramData\\Anaconda3\\envs\\deeplearning\\lib\\site-packages\\IPython\\core\\interactiveshell.py\", line 2077, in showtraceback\n",
      "    stb = value._render_traceback_()\n",
      "AttributeError: 'TypeError' object has no attribute '_render_traceback_'\n",
      "\n",
      "During handling of the above exception, another exception occurred:\n",
      "\n",
      "Traceback (most recent call last):\n",
      "  File \"C:\\ProgramData\\Anaconda3\\envs\\deeplearning\\lib\\site-packages\\IPython\\core\\ultratb.py\", line 1101, in get_records\n",
      "    return _fixed_getinnerframes(etb, number_of_lines_of_context, tb_offset)\n",
      "  File \"C:\\ProgramData\\Anaconda3\\envs\\deeplearning\\lib\\site-packages\\IPython\\core\\ultratb.py\", line 248, in wrapped\n",
      "    return f(*args, **kwargs)\n",
      "  File \"C:\\ProgramData\\Anaconda3\\envs\\deeplearning\\lib\\site-packages\\IPython\\core\\ultratb.py\", line 281, in _fixed_getinnerframes\n",
      "    records = fix_frame_records_filenames(inspect.getinnerframes(etb, context))\n",
      "  File \"C:\\ProgramData\\Anaconda3\\envs\\deeplearning\\lib\\inspect.py\", line 1500, in getinnerframes\n",
      "    frameinfo = (tb.tb_frame,) + getframeinfo(tb, context)\n",
      "  File \"C:\\ProgramData\\Anaconda3\\envs\\deeplearning\\lib\\inspect.py\", line 1458, in getframeinfo\n",
      "    filename = getsourcefile(frame) or getfile(frame)\n",
      "  File \"C:\\ProgramData\\Anaconda3\\envs\\deeplearning\\lib\\inspect.py\", line 696, in getsourcefile\n",
      "    if getattr(getmodule(object, filename), '__loader__', None) is not None:\n",
      "  File \"C:\\ProgramData\\Anaconda3\\envs\\deeplearning\\lib\\inspect.py\", line 733, in getmodule\n",
      "    if ismodule(module) and hasattr(module, '__file__'):\n",
      "  File \"C:\\ProgramData\\Anaconda3\\envs\\deeplearning\\lib\\site-packages\\tensorflow\\__init__.py\", line 50, in __getattr__\n",
      "    module = self._load()\n",
      "  File \"C:\\ProgramData\\Anaconda3\\envs\\deeplearning\\lib\\site-packages\\tensorflow\\__init__.py\", line 44, in _load\n",
      "    module = _importlib.import_module(self.__name__)\n",
      "  File \"C:\\ProgramData\\Anaconda3\\envs\\deeplearning\\lib\\importlib\\__init__.py\", line 127, in import_module\n",
      "    return _bootstrap._gcd_import(name[level:], package, level)\n",
      "  File \"<frozen importlib._bootstrap>\", line 1006, in _gcd_import\n",
      "  File \"<frozen importlib._bootstrap>\", line 983, in _find_and_load\n",
      "  File \"<frozen importlib._bootstrap>\", line 965, in _find_and_load_unlocked\n",
      "ModuleNotFoundError: No module named 'tensorflow_core.estimator'\n"
     ]
    }
   ],
   "source": [
    "# define the middle layer of neutral network\n",
    "Weight_L1 = tf.Variable(tf.random_normal([1,10]))\n",
    "biases_L1 = tf.Variable(tf.zeros([1,10]))\n",
    "WeightPlusBias_L1 = tf.matmul(x,Weights_L1)+biases_L1\n",
    "L1 = tf.nn.tanh(WeightPlusBias_L1)\n",
    "\n",
    "# define the output layer of neutral network\n",
    "Weights_L2=tf.Variable(tf.random_normal([10,1]))\n",
    "biases_L2=tf.Variable(tf.zeros([1,1]))  \n",
    "WeightPlusBias_L2=tf.matmul(L1,Weights_L2)+biases_L2\n",
    "prediction=tf.nn.tanh(WeightPlusBias_L2)   \n",
    "\n",
    "# define the output layer of neutral network\n",
    "Weights_L2=tf.Variable(tf.random_normal([10,1]))\n",
    "biases_L2=tf.Variable(tf.zeros([1,1]))  \n",
    "WeightPlusBias_L2=tf.matmul(L1,Weights_L2)+biases_L2\n",
    "prediction=tf.nn.tanh(WeightPlusBias_L2)\n",
    "\n",
    "with tf.Session() as sess:\n",
    "    sess.run(tf.global_variables_initializer())\n",
    "    for i in range(2000):\n",
    "        sess.run(train_step,feed_dict={x:x_data,y:y_data})\n",
    "    prediction_value=sess.run(prediction,feed_dict={x:x_data})\n",
    "    #draw picture\n",
    "    plt.figure()\n",
    "    plt.scatter(x_data,y_data)\n",
    "    plt.plot(x_data,prediction_value,'r-',lw=5)   #曲线是预测值\n",
    "    plt.show()"
   ]
  },
  {
   "cell_type": "code",
   "execution_count": null,
   "id": "5a6b14f5",
   "metadata": {},
   "outputs": [],
   "source": []
  }
 ],
 "metadata": {
  "kernelspec": {
   "display_name": "deeplearning",
   "language": "python",
   "name": "deeplearning"
  },
  "language_info": {
   "codemirror_mode": {
    "name": "ipython",
    "version": 3
   },
   "file_extension": ".py",
   "mimetype": "text/x-python",
   "name": "python",
   "nbconvert_exporter": "python",
   "pygments_lexer": "ipython3",
   "version": "3.7.1"
  }
 },
 "nbformat": 4,
 "nbformat_minor": 5
}
